<?xml version='1.0' encoding='utf-8'?>
<robot name="urdf_full">

  <link name="base_link">
    <inertial>
      <origin xyz="0 0 0" rpy="0 0 0" />
      <mass value="0.001" />
      <inertia ixx="1e-6" ixy="0" ixz="0" iyy="1e-6" iyz="0" izz="1e-6" />
    </inertial>
  </link>
  <joint name="base_link_to_model" type="fixed">
    
    <origin xyz="0.000000 0.000000 0.000000" rpy="0.000000 0.000000 0.000000" />
    <parent link="base_link" />
    <child link="base_link_model" />
  </joint>
  <link name="base_link_model">
    <inertial>
      <origin xyz="0.000000 0.000000 0.000000" rpy="0.000000 0.000000 0.000000" />
      <mass value="124.0" />
      <inertia ixx="4.585" ixy="0" ixz="0" iyy="6.295" iyz="0" izz="9.067" />
    </inertial>
    <visual>
      <origin xyz="-0.182618 -0.180701 0.147244" rpy="-1.570800 -0.000000 1.570800" />
      <geometry>
        <mesh filename="package://hit25_auv/meshes/base_link.STL" />
      </geometry>
      <material name="">
        <color rgba="0.792156862745098 0.819607843137255 0.933333333333333 1" />
      </material>
    </visual>
    <collision>
      <origin xyz="-0.182618 -0.180701 0.147244" rpy="-1.570800 -0.000000 1.570800" />
      <geometry>
        <mesh filename="package://hit25_auv/meshes/base_link.STL" />
      </geometry>
    </collision>
    <collision name="buoyancy_collision">
      <origin xyz="0.000000 -0.000000 -0.000000" rpy="-1.570800 -0.000000 1.570800" />
      <geometry>
        <box size="0.718 0.593 0.294" />
      </geometry>
    </collision>
  </link>
  <gazebo>
    <plugin name="gazebo_ros_force_base_link" filename="libgazebo_ros_force.so">
      <ros>
        <namespace>/hit25_auv</namespace>
        <remapping>gazebo_ros_force:=base_link_wrench</remapping>
      </ros>
      <link_name>base_link</link_name>
      <force_frame>link</force_frame>
    </plugin>
  </gazebo>
  <link name="VER_LF">
    <inertial>
      <origin xyz="0 0 0" rpy="0 0 0" />
      <mass value="0.01" />
      <inertia ixx="0.0001" ixy="0" ixz="0" iyy="0.0001" iyz="0" izz="0.0001" />
    </inertial>
    <visual>
      <origin xyz="0 0 0" rpy="0 0 0" />
      <geometry>
        <mesh filename="package://hit25_auv/meshes/VER_LF.STL" />
      </geometry>
      <material name="">
        <color rgba="0.792156862745098 0.819607843137255 0.933333333333333 1" />
      </material>
    </visual>
    </link>
  <joint name="VER_LF_J" type="continuous">
    <origin xyz="-0.234618 0.148999 -0.081162" rpy="3.141593 -1.570793 -3.141589" />
    <parent link="base_link_model" />
    <child link="VER_LF" />
    <axis xyz="1 0 0" />
  </joint>
  <link name="VER_LR">
    <inertial>
      <origin xyz="0 0 0" rpy="0 0 0" />
      <mass value="0.01" />
      <inertia ixx="0.0001" ixy="0" ixz="0" iyy="0.0001" iyz="0" izz="0.0001" />
    </inertial>
    <visual>
      <origin xyz="0 0 0" rpy="0 0 0" />
      <geometry>
        <mesh filename="package://hit25_auv/meshes/VER_LR.STL" />
      </geometry>
      <material name="">
        <color rgba="0.792156862745098 0.819607843137255 0.933333333333333 1" />
      </material>
    </visual>
    </link>
  <joint name="VER_LR_J" type="continuous">
    <origin xyz="-0.234617 -0.171001 -0.081162" rpy="3.141593 -1.570793 -3.141589" />
    <parent link="base_link_model" />
    <child link="VER_LR" />
    <axis xyz="1 0 0" />
  </joint>
  <link name="VER_RF">
    <inertial>
      <origin xyz="0 0 0" rpy="0 0 0" />
      <mass value="0.01" />
      <inertia ixx="0.0001" ixy="0" ixz="0" iyy="0.0001" iyz="0" izz="0.0001" />
    </inertial>
    <visual>
      <origin xyz="0 0 0" rpy="0 0 0" />
      <geometry>
        <mesh filename="package://hit25_auv/meshes/VER_RF.STL" />
      </geometry>
      <material name="">
        <color rgba="0.792156862745098 0.819607843137255 0.933333333333333 1" />
      </material>
    </visual>
    </link>
  <joint name="VER_RF_J" type="continuous">
    <origin xyz="0.234382 0.149001 -0.081164" rpy="-0.785391 -1.570791 -2.356191" />
    <parent link="base_link_model" />
    <child link="VER_RF" />
    <axis xyz="1 0 0" />
  </joint>
  <link name="VER_RR">
    <inertial>
      <origin xyz="0 0 0" rpy="0 0 0" />
      <mass value="0.01" />
      <inertia ixx="0.0001" ixy="0" ixz="0" iyy="0.0001" iyz="0" izz="0.0001" />
    </inertial>
    <visual>
      <origin xyz="0 0 0" rpy="0 0 0" />
      <geometry>
        <mesh filename="package://hit25_auv/meshes/VER_RR.STL" />
      </geometry>
      <material name="">
        <color rgba="0.792156862745098 0.819607843137255 0.933333333333333 1" />
      </material>
    </visual>
    </link>
  <joint name="VER_RR_J" type="continuous">
    <origin xyz="0.234383 -0.170999 -0.081164" rpy="-0.785391 -1.570791 -2.356191" />
    <parent link="base_link_model" />
    <child link="VER_RR" />
    <axis xyz="1 0 0" />
  </joint>
  <link name="YAW_LF">
    <inertial>
      <origin xyz="0 0 0" rpy="0 0 0" />
      <mass value="0.01" />
      <inertia ixx="0.0001" ixy="0" ixz="0" iyy="0.0001" iyz="0" izz="0.0001" />
    </inertial>
    <visual>
      <origin xyz="0 0 0" rpy="0 0 0" />
      <geometry>
        <mesh filename="package://hit25_auv/meshes/YAW_LF.STL" />
      </geometry>
      <material name="">
        <color rgba="0.792156862745098 0.819607843137255 0.933333333333333 1" />
      </material>
    </visual>
    </link>
  <joint name="YAW_LF_J" type="continuous">
    <origin xyz="-0.182910 0.082889 0.027244" rpy="0.000001 -0.000002 0.825880" />
    <parent link="base_link_model" />
    <child link="YAW_LF" />
    <axis xyz="1 0 0" />
  </joint>
  <link name="YAW_LR">
    <inertial>
      <origin xyz="0 0 0" rpy="0 0 0" />
      <mass value="0.01" />
      <inertia ixx="0.0001" ixy="0" ixz="0" iyy="0.0001" iyz="0" izz="0.0001" />
    </inertial>
    <visual>
      <origin xyz="0 0 0" rpy="0 0 0" />
      <geometry>
        <mesh filename="package://hit25_auv/meshes/YAW_LR.STL" />
      </geometry>
      <material name="">
        <color rgba="0.792156862745098 0.819607843137255 0.933333333333333 1" />
      </material>
    </visual>
    </link>
  <joint name="YAW_LR_J" type="continuous">
    <origin xyz="-0.183273 -0.097611 0.027244" rpy="0.000001 0.000003 2.356200" />
    <parent link="base_link_model" />
    <child link="YAW_LR" />
    <axis xyz="1 0 0" />
  </joint>
  <link name="YAW_RF">
    <inertial>
      <origin xyz="0 0 0" rpy="0 0 0" />
      <mass value="0.01" />
      <inertia ixx="0.0001" ixy="0" ixz="0" iyy="0.0001" iyz="0" izz="0.0001" />
    </inertial>
    <visual>
      <origin xyz="0 0 0" rpy="0 0 0" />
      <geometry>
        <mesh filename="package://hit25_auv/meshes/YAW_RF.STL" />
      </geometry>
      <material name="">
        <color rgba="0.792156862745098 0.819607843137255 0.933333333333333 1" />
      </material>
    </visual>
    </link>
  <joint name="YAW_RF_J" type="continuous">
    <origin xyz="0.183512 0.083041 0.027246" rpy="0.000001 0.000003 2.356200" />
    <parent link="base_link_model" />
    <child link="YAW_RF" />
    <axis xyz="1 0 0" />
  </joint>
  <link name="YAW_RR">
    <inertial>
      <origin xyz="0 0 0" rpy="0 0 0" />
      <mass value="0.01" />
      <inertia ixx="0.0001" ixy="0" ixz="0" iyy="0.0001" iyz="0" izz="0.0001" />
    </inertial>
    <visual>
      <origin xyz="0 0 0" rpy="0 0 0" />
      <geometry>
        <mesh filename="package://hit25_auv/meshes/YAW_RR.STL" />
      </geometry>
      <material name="">
        <color rgba="0.792156862745098 0.819607843137255 0.933333333333333 1" />
      </material>
    </visual>
    </link>
  <joint name="YAW_RR_J" type="continuous">
    <origin xyz="0.182883 -0.097054 0.027245" rpy="0.000001 -0.000003 0.782910" />
    <parent link="base_link_model" />
    <child link="YAW_RR" />
    <axis xyz="1 0 0" />
  </joint>
  <link name="camera">
    <inertial>
      <origin xyz="0 0 0" rpy="0 0 0" />
      <mass value="0.01" />
      <inertia ixx="0.0001" ixy="0" ixz="0" iyy="0.0001" iyz="0" izz="0.0001" />
    </inertial>
    <visual>
      <origin xyz="0 0 0" rpy="0 0 0" />
      <geometry>
        <box size="0.05 0.05 0.05" />
      </geometry>
      <material name="camera_black">
        <color rgba="0.1 0.1 0.1 1" />
      </material>
    </visual>
  </link>
  <joint name="camera_j" type="fixed">
    <origin xyz="0.002502 0.184100 -0.003535" rpy="0.000000 -0.000000 1.570800" />
    <parent link="base_link_model" />
    <child link="camera" />
    <axis xyz="0 0 0" />
  </joint>
  <link name="imu">
    <inertial>
      <origin xyz="0 0 0" rpy="0 0 0" />
      <mass value="0.02" />
      <inertia ixx="0.0002" ixy="0" ixz="0" iyy="0.0002" iyz="0" izz="0.0002" />
    </inertial>
    <visual>
      <origin xyz="0 0 0" rpy="0 0 0" />
      <geometry>
        <box size="0.04 0.03 0.02" />
      </geometry>
      <material name="imu_blue">
        <color rgba="0.2 0.4 0.9 1" />
      </material>
    </visual>
  </link>
  <joint name="imu_j" type="fixed">
    
    <origin xyz="0 0 0.03" rpy="0 0 0" />
    <parent link="base_link" />
    <child link="imu" />
    <axis xyz="0 0 0" />
  </joint>
  <link name="dvl">
    <inertial>
      <origin xyz="0 0 0" rpy="0 0 0" />
      <mass value="0.05" />
      <inertia ixx="0.0004" ixy="0" ixz="0" iyy="0.0004" iyz="0" izz="0.0004" />
    </inertial>
    <visual>
      <origin xyz="0 0 0" rpy="0 0 0" />
      <geometry>
        <cylinder radius="0.03" length="0.05" />
      </geometry>
      <material name="dvl_gray">
        <color rgba="0.4 0.4 0.4 1" />
      </material>
    </visual>
  </link>
  <joint name="dvl_j" type="fixed">
    
    <origin xyz="0 0 -0.06" rpy="0 0 0" />
    <parent link="base_link" />
    <child link="dvl" />
    <axis xyz="0 0 0" />
  </joint>
  <gazebo reference="camera">
    <sensor type="camera" name="front_camera">
      <always_on>true</always_on>
      <update_rate>30</update_rate>
      <visualize>false</visualize>
      <camera>
        <horizontal_fov>1.047</horizontal_fov>
        <image>
          <width>640</width>
          <height>480</height>
          <format>R8G8B8</format>
        </image>
        <clip>
          <near>0.05</near>
          <far>50</far>
        </clip>
      </camera>
      <plugin name="gazebo_ros_camera" filename="libgazebo_ros_camera.so">
        <ros>
          <namespace>/</namespace>
        </ros>
        <camera_name>camera/color</camera_name>
        <image_topic_name>image_raw</image_topic_name>
        <camera_info_topic_name>camera_info</camera_info_topic_name>
        <frame_name>camera</frame_name>
      </plugin>
    </sensor>
  </gazebo>
  <link name="pixhawk">
    <inertial>
      <origin xyz="0 0 0" rpy="0 0 0" />
      <mass value="0.01" />
      <inertia ixx="0.0001" ixy="0" ixz="0" iyy="0.0001" iyz="0" izz="0.0001" />
    </inertial>
    <visual>
      <origin xyz="0 0 0" rpy="0 0 0" />
      <geometry>
        <box size="0.08 0.05 0.02" />
      </geometry>
      <material name="pixhawk_gray">
        <color rgba="0.2 0.2 0.2 1" />
      </material>
    </visual>
  </link>
  <joint name="pixhawk_j" type="fixed">
    <origin xyz="0.000002 0.050900 0.019965" rpy="0.000000 -0.000000 1.570800" />
    <parent link="base_link_model" />
    <child link="pixhawk" />
    <axis xyz="0 0 0" />
  </joint>
  <link name="depth">
    <inertial>
      <origin xyz="0 0 0" rpy="0 0 0" />
      <mass value="0.01" />
      <inertia ixx="0.0001" ixy="0" ixz="0" iyy="0.0001" iyz="0" izz="0.0001" />
    </inertial>
    <visual>
      <origin xyz="0 0 0" rpy="0 0 0" />
      <geometry>
        <box size="0.04 0.04 0.02" />
      </geometry>
      <material name="depth_blue">
        <color rgba="0.1 0.2 0.6 1" />
      </material>
    </visual>
  </link>
  <joint name="depth_j" type="fixed">
    <origin xyz="0.030313 -0.192525 -0.010255" rpy="0.000000 -0.000000 1.570800" />
    <parent link="base_link_model" />
    <child link="depth" />
    <axis xyz="0 0 0" />
  </joint>
</robot>
